Workbook

Sheet Task1-1 cleaned
A1: Post ID | B1: Platform | C1: Date | D1: Content Type | E1: Post Text | F1: Likes | G1: Shares | H1: Comments | I1: Impressions | J1: Reach | K1: Clicks | L1: Hashtags Used
A2: P001 | B2: Twitter | C2: 45649 | D2: Reel | E2: Check out our latest reel on twitter! | F2: 1461 | G2: 184 | H2: 344 | I2: 21915 | J2: 21675 | K2: 15 | L2: #LiveForNow | M2: #AnytimeIsPepsiTime
A3: P002 | B3: Twitter | C3: 45750 | D3: Text | E3: Check out our latest text on twitter! | F3: 4054 | G3: 389 | H3: 493 | I3: 64864 | J3: 64383 | K3: 117 | L3: #PepsiCoRefresh | M3: #BetterWithPepsi
A4: P003 | B4: YouTube | C4: 45789 | D4: Reel | E4: Check out our latest reel on youtube! | F4: 2795 | G4: 105 | H4: 49 | I4: 53105 | J4: 52307 | K4: 204 | L4: #PepsiCoRefresh
A5: P004 | B5: Instagram | C5: 45516 | D5: Story | E5: Check out our latest story on instagram! | F5: 2404 | G5: 363 | H5: 138 | I5: 19232 | J5: 18636 | K5: 128 | L5: #ThirstyForMore
A6: P005 | B6: YouTube | C6: 45469 | D6: Reel | E6: Check out our latest reel on youtube! | F6: 3557 | G6: 687 | H6: 424 | I6: 71140 | J6: 70701 | K6: 224 | L6: #ThirstyForMore | M6: #PepsiCoRefresh
A7: P006 | B7: Facebook | C7: 45596 | D7: Carousel | E7: Check out our latest carousel on facebook! | F7: 2945 | G7: 930 | H7: 355 | I7: 23560 | J7: 23275 | K7: 256 | L7: #PepsiCoRefresh
A8: P007 | B8: Twitter | C8: 45467 | D8: Carousel | E8: Check out our latest carousel on twitter! | F8: 3860 | G8: 201 | H8: 279 | I8: 61760 | J8: 61660 | K8: 235 | L8: #PepsiCoRefresh
A9: P008 | B9: YouTube | C9: 45486 | D9: Image | E9: Check out our latest image on youtube! | F9: 3929 | G9: 262 | H9: 278 | I9: 43219 | J9: 42841 | K9: 39 | L9: #ThirstyForMore
A10: P009 | B10: Facebook | C10: 45534 | D10: Text | E10: Check out our latest text on facebook! | F10: 3784 | G10: 808 | H10: 404 | I10: 56760 | J10: 56343 | K10: 131 | L10: #PepsiCoRefresh
A11: P010 | B11: Facebook | C11: 45727 | D11: Image | E11: Check out our latest image on facebook! | F11: 4241 | G11: 902 | H11: 47 | I11: 72097 | J11: 71598 | K11: 167 | L11: #PepsiCoRefresh
A12: P011 | B12: Instagram | C12: 45690 | D12: Story | E12: Check out our latest story on instagram! | F12: 1792 | G12: 614 | H12: 497 | I12: 25088 | J12: 24675 | K12: 65 | L12: #LiveForNow
A13: P012 | B13: Facebook | C13: 45494 | D13: Reel | E13: Check out our latest reel on facebook! | F13: 1946 | G13: 686 | H13: 377 | I13: 23352 | J13: 22982 | K13: 213 | L13: #LiveForNow
A14: P013 | B14: YouTube | C14: 45614 | D14: Carousel | E14: Check out our latest carousel on youtube! | F14: 1171 | G14: 286 | H14: 231 | I14: 22249 | J14: 21282 | K14: 114 | L14: #ThirstyForMore
A15: P014 | B15: Facebook | C15: 45704 | D15: Story | E15: Check out our latest story on facebook! | F15: 4242 | G15: 555 | H15: 131 | I15: 33936 | J15: 33802 | K15: 265 | L15: #LiveForNow
A16: P015 | B16: Facebook | C16: 45589 | D16: Video | E16: Check out our latest video on facebook! | F16: 3888 | G16: 604 | H16: 128 | I16: 77760 | J16: 77167 | K16: 20 | L16: #LiveForNow
A17: P016 | B17: Facebook | C17: 45530 | D17: Text | E17: Check out our latest text on facebook! | F17: 3452 | G17: 377 | H17: 360 | I17: 55232 | J17: 55075 | K17: 87 | L17: #LiveForNow
A18: P017 | B18: Facebook | C18: 45782 | D18: Text | E18: Check out our latest text on facebook! | F18: 4441 | G18: 511 | H18: 70 | I18: 53292 | J18: 53082 | K18: 159 | L18: #ThirstyForMore
... A23: P022 | B23: Facebook | C23: 45715 | D23: Text | E23: Check out our latest text on facebook! | F23: 1570 | G23: 187 | H23: 260 | I23: 25120 | J23: 24613 | K23: 133 | L23: #PepsiCoRefresh
A24: P023 | B24: Facebook | C24: 45602 | D24: Video | E24: Check out our latest video on facebook! | F24: 1606 | G24: 547 | H24: 316 | I24: 32120 | J24: 31736 | K24: 225 | L24: #PepsiCoRefresh | M24: #AnytimeIsPepsiTime
A25: P024 | B25: Facebook | C25: 45680 | D25: Video | E25: Check out our latest video on facebook! | F25: 3961 | G25: 761 | H25: 131 | I25: 67337 | J25: 66615 | K25: 161 | L25: #LiveForNow
A26: P025 | B26: Twitter | C26: 45757 | D26: Carousel | E26: Check out our latest carousel on twitter! | F26: 3128 | G26: 211 | H26: 197 | I26: 59432 | J26: 59182 | K26: 238 | L26: #ThirstyForMore
A27: P026 | B27: YouTube | C27: 45752 | D27: Reel | E27: Check out our latest reel on youtube! | F27: 3009 | G27: 413 | H27: 358 | I27: 42126 | J27: 41309 | K27: 211 | L27: #LiveForNow
A28: P027 | B28: YouTube | C28: 45552 | D28: Text | E28: Check out our latest text on youtube! | F28: 2076 | G28: 195 | H28: 104 | I28: 33216 | J28: 32244 | K28: 51 | L28: #LiveForNow
A29: P028 | B29: Instagram | C29: 45720 | D29: Video | E29: Check out our latest video on instagram! | F29: 432 | G29: 624 | H29: 123 | I29: 6912 | J29: 6259 | K29: 79 | L29: #LiveForNow
A30: P029 | B30: Instagram | C30: 45688 | D30: Carousel | E30: Check out our latest carousel on instagram! | F30: 2566 | G30: 118 | H30: 37 | I30: 12830 | J30: 12264 | K30: 221 | L30: #LiveForNow
A31: P030 | B31: Instagram | C31: 45713 | D31: Video | E31: Check out our latest video on instagram! | F31: 3095 | G31: 39 | H31: 78 | I31: 55710 | J31: 54808 | K31: 93 | L31: #ThirstyForMore
A32: P031 | B32: Instagram | C32: 45642 | D32: Text | E32: Check out our latest text on instagram! | F32: 438 | G32: 153 | H32: 275 | I32: 3066 | J32: 2701 | K32: 282 | L32: #PepsiCoRefresh
A33: P032 | B33: Twitter | C33: 45504 | D33: Carousel | E33: Check out our latest carousel on twitter! | F33: 2278 | G33: 10 | H33: 321 | I33: 13668 | J33: 12676 | K33: 275 | L33: #ThirstyForMore
A34: P033 | B34: Facebook | C34: 45525 | D34: Image | E34: Check out our latest image on facebook! | F34: 1407 | G34: 400 | H34: 351 | I34: 16884 | J34: 15954 | K34: 113 | L34: #PepsiCoRefresh
A35: P034 | B35: Facebook | C35: 45742 | D35: Text | E35: Check out our latest text on facebook! | F35: 1652 | G35: 89 | H35: 357 | I35: 29736 | J35: 28771 | K35: 215 | L35: #PepsiCoRefresh
A36: P035 | B36: Instagram | C36: 45626 | D36: Video | E36: Check out our latest video on instagram! | F36: 3775 | G36: 16 | H36: 239 | I36: 33975 | J36: 33310 | K36: 271 | L36: #LiveForNow
... A53: P052 | B53: Facebook | C53: 45660 | D53: Image | E53: Check out our latest image on facebook! | F53: 947 | G53: 338 | H53: 350 | I53: 10417 | J53: 9730 | K53: 34 | L53: #PepsiCoRefresh
A54: P053 | B54: YouTube | C54: 45712 | D54: Carousel | E54: Check out our latest carousel on youtube! | F54: 804 | G54: 639 | H54: 43 | I54: 4020 | J54: 3144 | K54: 11 | L54: #ThirstyForMore | M54: #BetterWithPepsi
A55: P054 | B55: YouTube | C55: 45729 | D55: Carousel | E55: Check out our latest carousel on youtube! | F55: 1686 | G55: 904 | H55: 472 | I55: 18546 | J55: 18171 | K55: 52 | L55: #LiveForNow
A56: P055 | B56: Facebook | C56: 45460 | D56: Image | E56: Check out our latest image on facebook! | F56: 1226 | G56: 119 | H56: 7 | I56: 14712 | J56: 14049 | K56: 123 | L56: #ThirstyForMore
A57: P056 | B57: Facebook | C57: 45644 | D57: Carousel | E57: Check out our latest carousel on facebook! | F57: 2946 | G57: 498 | H57: 367 | I57: 29460 | J57: 28527 | K57: 60 | L57: #LiveForNow
A58: P057 | B58: Twitter | C58: 45586 | D58: Video | E58: Check out our latest video on twitter! | F58: 2825 | G58: 535 | H58: 295 | I58: 45200 | J58: 44739 | K58: 169 | L58: #PepsiCoRefresh
A59: P058 | B59: Instagram | C59: 45762 | D59: Reel | E59: Check out our latest reel on instagram! | F59: 103 | G59: 770 | H59: 19 | I59: 1030 | J59: 410 | K59: 262 | L59: #PepsiCoRefresh
A60: P059 | B60: Instagram | C60: 45465 | D60: Text | E60: Check out our latest text on instagram! | F60: 2180 | G60: 263 | H60: 387 | I60: 30520 | J60: 30059 | K60: 174 | L60: #ThirstyForMore
...

Sheet Task1-2 cleaned
A1: Week_Start_Date | B1: Platform | C1: New_Followers | D1: Unfollows | E1: Total_Followers | F1: Engagement_Rate | G1: Ad_Spend
A2: 45446 | B2: Instagram | C2: 1135 | D2: 88 | E2: 344084 | F2: 8.06 | G2: 5904
A3: 45446 | B3: Facebook | C3: 1312 | D3: 310 | E3: 42654 | F3: 4.98 | G3: 9566
A4: 45446 | B4: Twitter | C4: 584 | D4: 169 | E4: 146834 | F4: 8.31 | G4: 26752
A5: 45446 | B5: YouTube | C5: 1535 | D5: 445 | E5: 395536 | F5: 4.11 | G5: 30671
A6: 45453 | B6: Instagram | C6: 656 | D6: 139 | E6: 49157 | F6: 9.05 | G6: 9920
A7: 45453 | B7: Facebook | C7: 1697 | D7: 414 | E7: 316555 | F7: 2.37 | G7: 7924
A8: 45453 | B8: Twitter | C8: 436 | D8: 250 | E8: 254347 | F8: 4.01 | G8: 8912
A9: 45453 | B9: YouTube | C9: 1197 | D9: 203 | E9: 413878 | F9: 3.16 | G9: 21205
A10: 45460 | B10: Instagram | C10: 1048 | D10: 155 | E10: 456946 | F10: 2.46 | G10: 11329
A11: 45460 | B11: Facebook | C11: 1753 | D11: 371 | E11: 169496 | F11: 8.11 | G11: 46670
A12: 45460 | B12: Twitter | C12: 1335 | D12: 40 | E12: 122732 | F12: 8.19 | G12: 22482
A13: 45460 | B13: YouTube | C13: 403 | D13: 66 | E13: 382851 | F13: 3.49 | G13: 24313
... A201: 45789 | B201: YouTube | C201: 119 | D201: 456 | E201: 82558 | F201: 6.81 | G201: 12174

Sheet Task1-3 cleaned
A1: Campaign_Name | B1: Start_Date | C1: End_Date | D1: Objective | E1: Total_Budget | F1: Target_Platforms | G1: Primary_Hashtags
A2: SummerSplash | B2: 45458 | C2: 45488 | D2: Brand Awareness | E2: 150000 | F2: Instagram,Facebook | G2: #ThirstyForMore | H2: #PepsiCoRefresh
A3: FestiveRadiance | B3: 45566 | C3: 45596 | D3: Engagement | E3: 200000 | F3: Instagram,YouTube | G3: #AnytimeIsPepsiTime
A4: NewYearRefresh | B4: 45651 | C4: 45667 | D4: Product Launch | E4: 250000 | F4: Facebook,Twitter | G4: #SmoothLikeNitroPepsi
A5: DailyWellness | B5: 45717 | C5: 45747 | D5: Traffic | E5: 180000 | F5: Instagram,Twitter | G5: #BetterWithPepsi | H5: #LiveForNow
I21: .

Sheet Task2-1 Engagement Analysis
A1: Post ID | B1: Platform | C1: Date | D1: Content Type | E1: Post Text | F1: Likes | G1: Shares | H1: Comments | I1: Impressions | J1: Reach | K1: Clicks | L1: Hashtags Used | O1: Engagement Rate
A2: P220 | B2: Instagram | C2: 45445 | D2: Story | E2: Check out our latest story on instagram! | F2: 84 | G2: 897 | H2: 85 | I2: 588 | J2: 8 | K2: 12 | L2: #ThirstyForMore | O2: =(F2 + G2 + H2) / I2 -> 1.8129252
A3: P058 | B3: Instagram | C3: 45762 | D3: Reel | E3: Check out our latest reel on instagram! | F3: 103 | G3: 770 | H3: 19 | I3: 1030 | J3: 410 | K3: 262 | L3: #PepsiCoRefresh | O3: =(F3 + G3 + H3) / I3 -> 0.86601942
A4: P232 | B4: Twitter | C4: 45776 | D4: Story | E4: Check out our latest story on twitter! | F4: 249 | G4: 592 | H4: 230 | I4: 1494 | J4: 1044 | K4: 201 | L4: #ThirstyForMore | O4: =(F4 + G4 + H4) / I4 -> 0.71686747
A5: P178 | B5: Instagram | C5: 45603 | D5: Video | E5: Check out our latest video on instagram! | F5: 129 | G5: 643 | H5: 136 | I5: 1290 | J5: 839 | K5: 238 | L5: #PepsiCoRefresh | O5: =(F5 + G5 + H5) / I5 -> 0.70387597
A6: P175 | B6: Instagram | C6: 45674 | D6: Reel | E6: Check out our latest reel on instagram! | F6: 142 | G6: 784 | H6: 183 | I6: 1704 | J6: 995 | K6: 154 | L6: #LiveForNow | O6: =(F6 + G6 + H6) / I6 -> 0.6508216
A7: P062 | B7: Twitter | C7: 45618 | D7: Carousel | E7: Check out our latest carousel on twitter! | F7: 53 | G7: 81 | H7: 379 | I7: 954 | J7: 7 | K7: 148 | L7: #PepsiCoRefresh | O7: =(F7 + G7 + H7) / I7 -> 0.53773585
A8: P264 | B8: Twitter | C8: 45687 | D8: Image | E8: Check out our latest image on twitter! | F8: 59 | G8: 163 | H8: 93 | I8: 590 | J8: 475 | K8: 293 | L8: #PepsiCoRefresh | O8: =(F8 + G8 + H8) / I8 -> 0.53389831
A9: P143 | B9: YouTube | C9: 45567 | D9: Carousel | E9: Check out our latest carousel on youtube! | F9: 80 | G9: 362 | H9: 80 | I9: 1040 | J9: 349 | K9: 117 | L9: #PepsiCoRefresh | O9: =(F9 + G9 + H9) / I9 -> 0.50192308
A10: P210 | B10: YouTube | C10: 45707 | D10: Image | E10: Check out our latest image on youtube! | F10: 257 | G10: 966 | H10: 398 | I10: 3341 | J10: 2753 | K10: 287 | L10: #LiveForNow | O10: =(F10 + G10 + H10) / I10 -> 0.48518408
A11: P070 | B11: Facebook | C11: 45749 | D11: Video | E11: Check out our latest video on facebook! | F11: 199 | G11: 772 | H11: 400 | I11: 3582 | J11: 2988 | K11: 43 | L11: #PepsiCoRefresh
A12: P214 | B12: Instagram | C12: 45649 | D12: Image | E12: Check out our latest image on instagram! | F12: 521 | G12: 746 | H12: 315 | I12: 4168 | J12: 3399 | K12: 282 | L12: #LiveForNow | O12: =(F12 + G12 + H12) / I12 -> 0.37955854
A13: P053 | B13: YouTube | C13: 45712 | D13: Carousel | E13: Check out our latest carousel on youtube! | F13: 804 | G13: 639 | H13: 43 | I13: 4020 | J13: 3144 | K13: 11 | L13: #ThirstyForMore | M13: #BetterWithPepsi | O13: =(F13 + G13 + H13) / I13 -> 0.36965174
A14: P102 | B14: Twitter | C14: 45553 | D14: Reel | E14: Check out our latest reel on twitter! | F14: 1000 | G14: 978 | H14: 162 | I14: 6000 | J14: 5221 | K14: 223 | L14: #ThirstyForMore | O14: =(F14 + G14 + H14) / I14 -> 0.35666667
A15: P124 | B15: YouTube | C15: 45753 | D15: Carousel | E15: Check out our latest carousel on youtube! | F15: 736 | G15: 771 | H15: 225 | I15: 5152 | J15: 4706 | K15: 19 | L15: #ThirstyForMore | O15: =(F15 + G15 + H15) / I15 -> 0.33618012
A16: P121 | B16: Instagram | C16: 45502 | D16: Story | E16: Check out our latest story on instagram! | F16: 498 | G16: 701 | H16: 412 | I16: 4980 | J16: 4185 | K16: 185 | L16: #LiveForNow | O16: =(F16 + G16 + H16) / I16 -> 0.32349398
A17: P224 | B17: Facebook | C17: 45790 | D17: Image | E17: Check out our latest image on facebook! | F17: 602 | G17: 594 | H17: 156 | I17: 4214 | J17: 3363 | K17: 164 | L17: #PepsiCoRefresh | O17: =(F17 + G17 + H17) / I17 -> 0.32083531
A18: P154 | B18: Instagram | C18: 45574 | D18: Carousel | E18: Check out our latest carousel on instagram! | F18: 985 | G18: 932 | H18: 287 | I18: 6895 | J18: 6757 | K18: 64 | L18: #LiveForNow | O18: =(F18 + G18 + H18) / I18 -> 0.31965192
A19: P119 | B19: Instagram | C19: 45695 | D19: Reel | E19: Check out our latest reel on instagram! | F19: 1970 | G19: 675 | H19: 478 | I19: 9850 | J19: 8924 | K19: 117 | L19: #LiveForNow | O19: =(F19 + G19 + H19) / I19 -> 0.31705584
A20: P287 | B20: Instagram | C20: 45519 | D20: Reel | E20: Check out our latest reel on instagram! | F20: 1164 | G20: 616 | H20: 324 | I20: 6984 | J20: 6636 | K20: 82 | L20: #ThirstyForMore | O20: =(F20 + G20 + H20) / I20 -> 0.30126002
A21: P204 | B21: Instagram | C21: 45658 | D21: Carousel | E21: Check out our latest carousel on instagram! | F21: 2234 | G21: 653 | H21: 432 | I21: 11170 | J21: 10569 | K21: 198 | L21: #LiveForNow | O21: =(F21 + G21 + H21) / I21 -> 0.29713518
A22: P066 | B22: Twitter | C22: 45499 | D22: Carousel | E22: Check out our latest carousel on twitter! | F22: 432 | G22: 171 | H22: 280 | I22: 3024 | J22: 2285 | K22: 184 | L22: #ThirstyForMore | O22: =(F22 + G22 + H22) / I22 -> 0.29199735
A23: P183 | B23: Instagram | C23: 45643 | D23: Story | E23: Check out our latest story on instagram! | F23: 360 | G23: 590 | H23: 393 | I23: 4680 | J23: 4322 | K23: 208 | L23: #LiveForNow | O23: =(F23 + G23 + H23) / I23 -> 0.28696581
A24: P031 | B24: Instagram | C24: 45642 | D24: Text | E24: Check out our latest text on instagram! | F24: 438 | G24: 153 | H24: 275 | I24: 3066 | J24: 2701 | K24: 282 | L24: #PepsiCoRefresh | O24: =(F24 + G24 + H24) / I24 -> 0.28245271
A25: P093 | B25: Instagram | C25: 45637 | D25: Video | E25: Check out our latest video on instagram! | F25: 1431 | G25: 951 | H25: 26 | I25: 8586 | J25: 8396 | K25: 150 | L25: #ThirstyForMore | O25: =(F25 + G25 + H25) / I25 -> 0.28045656
... A45: P159 | B45: Facebook | C45: 45621 | D45: Story | E45: Check out our latest story on facebook! | F45: 2120 | G45: 158 | H45: 488 | I45: 12720 | J45: 12085 | K45: 17 | L45: #LiveForNow | O45: =(F45 + G45 + H45) / I45 -> 0.21745283
A46: P146 | B46: YouTube | C46: 45448 | D46: Reel | E46: Check out our latest reel on youtube! | F46: 3065 | G46: 772 | H46: 142 | I46: 18390 | J46: 17875 | K46: 200 | L46: #ThirstyForMore | M46: #AnytimeIsPepsiTime | O46: =(F46 + G46 + H46) / I46 -> 0.21636759
A47: P029 | B47: Instagram | C47: 45688 | D47: Carousel | E47: Check out our latest carousel on instagram! | F47: 2566 | G47: 118 | H47: 37 | I47: 12830 | J47: 12264 | K47: 221 | L47: #LiveForNow | O47: =(F47 + G47 + H47) / I47 -> 0.21208106
A48: P137 | B48: Facebook | C48: 45504 | D48: Video | E48: Check out our latest video on facebook! | F48: 3008 | G48: 94 | H48: 37 | I48: 15040 | J48: 14639 | K48: 277 | L48: #LiveForNow | O48: =(F48 + G48 + H48) / I48 -> 0.20871011
A49: P087 | B49: Twitter | C49: 45449 | D49: Video | E49: Check out our latest video on twitter! | F49: 1436 | G49: 765 | H49: 496 | I49: 12924 | J49: 12701 | K49: 197 | L49: #LiveForNow | O49: =(F49 + G49 + H49) / I49 -> 0.20868152
A50: P271 | B50: Instagram | C50: 45582 | D50: Video | E50: Check out our latest video on instagram! | F50: 3575 | G50: 749 | H50: 111 | I50: 21450 | J50: 20785 | K50: 195 | L50: #ThirstyForMore | O50: =(F50 + G50 + H50) / I50 -> 0.20675991
A51: P077 | B51: Facebook | C51: 45720 | D51: Story | E51: Check out our latest story on facebook! | F51: 1249 | G51: 116 | H51: 420 | I51: 8743 | J51: 8538 | K51: 63 | L51: #PepsiCoRefresh | O51: =(F51 + G51 + H51) / I51 -> 0.20416333
A52: P136 | B52: Instagram | C52: 45484 | D52: Text | E52: Check out our latest text on instagram! | F52: 3134 | G52: 888 | H52: 444 | I52: 21938 | J52: 21337 | K52: 130 | L52: #ThirstyForMore | O52: =(F52 + G52 + H52) / I52 -> 0.20357371
A53: P258 | B53: Instagram | C53: 45509 | D53: Story | E53: Check out our latest story on instagram! | F53: 3601 | G53: 695 | H53: 75 | I53: 21606 | J53: 21454 | K53: 172 | L53: #ThirstyForMore | O53: =(F53 + G53 + H53) / I53 -> 0.20230492
A54: P276 | B54: Twitter | C54: 45450 | D54: Carousel | E54: Check out our latest carousel on twitter! | F54: 1556 | G54: 195 | H54: 131 | I54: 9336 | J54: 8875 | K54: 137 | L54: #PepsiCoRefresh | O54: =(F54 + G54 + H54) / I54 -> 0.20158526
A55: P148 | B55: Instagram | C55: 45762 | D55: Video | E55: Check out our latest video on instagram! | F55: 4133 | G55: 466 | H55: 327 | I55: 24798 | J55: 24620 | K55: 176 | L55: #ThirstyForMore | O55: =(F55 + G55 + H55) / I55 -> 0.19864505
A56: P198 | B56: Twitter | C56: 45549 | D56: Image | E56: Check out our latest image on twitter! | F56: 1048 | G56: 374 | H56: 450 | I56: 9432 | J56: 8882 | K56: 158 | L56: #PepsiCoRefresh | O56: =(F56 + G56 + H56) / I56 -> 0.19847328
A57: P152 | B57: Facebook | C57: 45769 | D57: Image | E57: Check out our latest image on facebook! | F57: 4804 | G57: 550 | H57: 270 | I57: 28824 | J57: 28370 | K57: 47 | L57: #ThirstyForMore | O57: =(F57 + G57 + H57) / I57 -> 0.19511518
A58: P286 | B58: YouTube | C58: 45560 | D58: Video | E58: Check out our latest video on youtube! | F58: 3389 | G58: 344 | H58: 229 | I58: 20334 | J58: 19443 | K58: 228 | L58: #LiveForNow | O58: =(F58 + G58 + H58) / I58 -> 0.19484607
... A80: P047 | B80: Twitter | C80: 45712 | D80: Carousel | E80: Check out our latest carousel on twitter! | F80: 2704 | G80: 752 | H80: 153 | I80: 21632 | J80: 20792 | K80: 127 | L80: #LiveForNow | O80: =(F80 + G80 + H80) / I80 -> 0.16683617
...

Sheet Task2 Pivot Table1
A1: Platform | B1: Content Type | C1: SUM of Likes | D1: SUM of Shares | E1: SUM of Comments
A2: Facebook | B2: Carousel | C2: 44476 | D2: 7400 | E2: 4589
B3: Image | C3: 71602 | D3: 12904 | E3: 6495
B4: Reel | C4: 36368 | D4: 5964 | E4: 3353
B5: Story | C5: 29405 | D5: 4950 | E5: 3223
B6: Text | C6: 31963 | D6: 4792 | E6: 3377
B7: Video | C7: 28947 | D7: 3171 | E7: 2263
A8: Facebook Total | C8: 242761 | D8: 39181 | E8: 23300
A9: Instagram | B9: Carousel | C9: 43948 | D9: 6975 | E9: 3890
B10: Image | C10: 34202 | D10: 5286 | E10: 2655
B11: Reel | C11: 32148 | D11: 8110 | E11: 3386
B12: Story | C12: 42649 | D12: 10049 | E12: 3846
B13: Text | C13: 25567 | D13: 5112 | E13: 1946
B14: Video | C14: 25770 | D14: 5912 | E14: 2128
A15: Instagram Total | C15: 204284 | D15: 41444 | E15: 17851
A16: Twitter | B16: Carousel | C16: 48649 | D16: 5791 | E16: 3607
B17: Image | C17: 43761 | D17: 7110 | E17: 5125
B18: Reel | C18: 27029 | D18: 4550 | E18: 1913
B19: Story | C19: 20466 | D19: 5090 | E19: 3026
B20: Text | C20: 31899 | D20: 4861 | E20: 3910
B21: Video | C21: 29593 | D21: 6326 | E21: 3299
A22: Twitter Total | C22: 201397 | D22: 33728 | E22: 20880
A23: YouTube | B23: Carousel | C23: 24926 | D23: 6305 | E23: 2422
B24: Image | C24: 23903 | D24: 4310 | E24: 2077
B25: Reel | C25: 32400 | D25: 4577 | E25: 2668
B26: Story | C26: 31968 | D26: 3866 | E26: 2012
B27: Text | C27: 27067 | D27: 3928 | E27: 1052
B28: Video | C28: 31285 | D28: 5586 | E28: 2589
A29: YouTube Total | C29: 171549 | D29: 28572 | E29: 12820
A30: Grand Total | C30: 819991 | D30: 142925 | E30: 74851

Sheet Task2 Pivot Table2
A1: Hashtags Used | B1: AVERAGE of Clicks | C1: Rank | E1: Platform | F1: SUM of Engagement Rate
A2: #LiveForNow | B2: 144.03883 | C2: =RANK(B2, B$2:B$50, FALSE) -> 4 | E2: Facebook | F2: 9.7410036
A3: #PepsiCoRefresh | B3: 157.02 | C3: =RANK(B3, B$2:B$50, FALSE) -> 1 | E3: Instagram | F3: 15.270114
A4: #ThirstyForMore | B4: 152.86598 | C4: =RANK(B4, B$2:B$50, FALSE) -> 2 | E4: Twitter | F4: 11.351042
A5: Grand Total | B5: 151.22 | C5: =RANK(B5, B$2:B$50, FALSE) -> 3 | E5: YouTube | F5: 7.7399113
E6: Grand Total | F6: 44.10207
A10: Top 10 Posts by Engagement Rate
A11: 1.8129252
A12: 0.86601942
A13: 0.71686747
A14: 0.70387597
A15: 0.6508216
A16: 0.53773585
A17: 0.53389831
A18: 0.50192308
A19: 0.48518408
A20: 0.38274707

Sheet Task3-1 Social Media Platform a
A1: Post ID | B1: Platform | C1: Date | D1: Content Type | E1: Post Text | F1: Likes | G1: Shares | H1: Comments | I1: Impressions | J1: Reach | K1: Clicks | L1: Hashtags Used | O1: Engagement Rate | P1: Total Engagement = Likes + Shares + Comments
A2: P220 | B2: Instagram | C2: 45445 | D2: Story | E2: Check out our latest story on instagram! | F2: 84 | G2: 897 | H2: 85 | I2: 588 | J2: 8 | K2: 12 | L2: #ThirstyForMore | O2: =(F2 + G2 + H2) / I2 -> 1.8129252 | P2: =F2 + G2 + H2 -> 1066
A3: P058 | B3: Instagram | C3: 45762 | D3: Reel | E3: Check out our latest reel on instagram! | F3: 103 | G3: 770 | H3: 19 | I3: 1030 | J3: 410 | K3: 262 | L3: #PepsiCoRefresh | O3: =(F3 + G3 + H3) / I3 -> 0.86601942 | P3: =F3 + G3 + H3 -> 892
A4: P232 | B4: Twitter | C4: 45776 | D4: Story | E4: Check out our latest story on twitter! | F4: 249 | G4: 592 | H4: 230 | I4: 1494 | J4: 1044 | K4: 201 | L4: #ThirstyForMore | O4: =(F4 + G4 + H4) / I4 -> 0.71686747 | P4: =F4 + G4 + H4 -> 1071
A5: P178 | B5: Instagram | C5: 45603 | D5: Video | E5: Check out our latest video on instagram! | F5: 129 | G5: 643 | H5: 136 | I5: 1290 | J5: 839 | K5: 238 | L5: #PepsiCoRefresh | O5: =(F5 + G5 + H5) / I5 -> 0.70387597 | P5: =F5 + G5 + H5 -> 908
A6: P175 | B6: Instagram | C6: 45674 | D6: Reel | E6: Check out our latest reel on instagram! | F6: 142 | G6: 784 | H6: 183 | I6: 1704 | J6: 995 | K6: 154 | L6: #LiveForNow | O6: =(F6 + G6 + H6) / I6 -> 0.6508216 | P6: =F6 + G6 + H6 -> 1109
A7: P062 | B7: Twitter | C7: 45618 | D7: Carousel | E7: Check out our latest carousel on twitter! | F7: 53 | G7: 81 | H7: 379 | I7: 954 | J7: 7 | K7: 148 | L7: #PepsiCoRefresh | O7: =(F7 + G7 + H7) / I7 -> 0.53773585 | P7: =F7 + G7 + H7 -> 513
A8: P264 | B8: Twitter | C8: 45687 | D8: Image | E8: Check out our latest image on twitter! | F8: 59 | G8: 163 | H8: 93 | I8: 590 | J8: 475 | K8: 293 | L8: #PepsiCoRefresh | O8: =(F8 + G8 + H8) / I8 -> 0.53389831 | P8: =F8 + G8 + H8 -> 315
A9: P143 | B9: YouTube | C9: 45567 | D9: Carousel | E9: Check out our latest carousel on youtube! | F9: 80 | G9: 362 | H9: 80 | I9: 1040 | J9: 349 | K9: 117 | L9: #PepsiCoRefresh | O9: =(F9 + G9 + H9) / I9 -> 0.50192308 | P9: =F9 + G9 + H9 -> 522
A10: P210 | B10: YouTube | C10: 45707 | D10: Image | E10: Check out our latest image on youtube! | F10: 257 | G10: 966 | H10: 398 | I10: 3341 | J10: 2753 | K10: 287 | L10: #LiveForNow | O10: =(F10 + G10 + H10) / I10 -> 0.48518408 | P10: =F10 + G10 + H10 -> 1621
A11: P070 | B11: Facebook | C11: 45749 | D11: Video | E11: Check out our latest video on facebook! | F11: 199 | G11: 772 | H11: 400 | I11: 3582 | J11: 2988 | K11: 43 | L11: #PepsiCoRefresh | P11: =F11 + G11 + H11 -> 1371
A12: P214 | B12: Instagram | C12: 45649 | D12: Image | E12: Check out our latest image on instagram! | F12: 521 | G12: 746 | H12: 315 | I12: 4168 | J12: 3399 | K12: 282 | L12: #LiveForNow | O12: =(F12 + G12 + H12) / I12 -> 0.37955854 | P12: =F12 + G12 + H12 -> 1582
A13: P053 | B13: YouTube | C13: 45712 | D13: Carousel | E13: Check out our latest carousel on youtube! | F13: 804 | G13: 639 | H13: 43 | I13: 4020 | J13: 3144 | K13: 11 | L13: #ThirstyForMore | M13: #BetterWithPepsi | O13: =(F13 + G13 + H13) / I13 -> 0.36965174 | P13: =F13 + G13 + H13 -> 1486
A14: P102 | B14: Twitter | C14: 45553 | D14: Reel | E14: Check out our latest reel on twitter! | F14: 1000 | G14: 978 | H14: 162 | I14: 6000 | J14: 5221 | K14: 223 | L14: #ThirstyForMore | O14: =(F14 + G14 + H14) / I14 -> 0.35666667 | P14: =F14 + G14 + H14 -> 2140
A15: P124 | B15: YouTube | C15: 45753 | D15: Carousel | E15: Check out our latest carousel on youtube! | F15: 736 | G15: 771 | H15: 225 | I15: 5152 | J15: 4706 | K15: 19 | L15: #ThirstyForMore | O15: =(F15 + G15 + H15) / I15 -> 0.33618012 | P15: =F15 + G15 + H15 -> 1732
A16: P121 | B16: Instagram | C16: 45502 | D16: Story | E16: Check out our latest story on instagram! | F16: 498 | G16: 701 | H16: 412 | I16: 4980 | J16: 4185 | K16: 185 | L16: #LiveForNow | O16: =(F16 + G16 + H16) / I16 -> 0.32349398 | P16: =F16 + G16 + H16 -> 1611
A17: P224 | B17: Facebook | C17: 45790 | D17: Image | E17: Check out our latest image on facebook! | F17: 602 | G17: 594 | H17: 156 | I17: 4214 | J17: 3363 | K17: 164 | L17: #PepsiCoRefresh | O17: =(F17 + G17 + H17) / I17 -> 0.32083531 | P17: =F17 + G17 + H17 -> 1352
A18: P154 | B18: Instagram | C18: 45574 | D18: Carousel | E18: Check out our latest carousel on instagram! | F18: 985 | G18: 932 | H18: 287 | I18: 6895 | J18: 6757 | K18: 64 | L18: #LiveForNow | O18: =(F18 + G18 + H18) / I18 -> 0.31965192 | P18: =F18 + G18 + H18 -> 2204
A19: P119 | B19: Instagram | C19: 45695 | D19: Reel | E19: Check out our latest reel on instagram! | F19: 1970 | G19: 675 | H19: 478 | I19: 9850 | J19: 8924 | K19: 117 | L19: #LiveForNow | O19: =(F19 + G19 + H19) / I19 -> 0.31705584 | P19: =F19 + G19 + H19 -> 3123
A20: P287 | B20: Instagram | C20: 45519 | D20: Reel | E20: Check out our latest reel on instagram! | F20: 1164 | G20: 616 | H20: 324 | I20: 6984 | J20: 6636 | K20: 82 | L20: #ThirstyForMore | O20: =(F20 + G20 + H20) / I20 -> 0.30126002 | P20: =F20 + G20 + H20 -> 2104
A21: P204 | B21: Instagram | C21: 45658 | D21: Carousel | E21: Check out our latest carousel on instagram! | F21: 2234 | G21: 653 | H21: 432 | I21: 11170 | J21: 10569 | K21: 198 | L21: #LiveForNow | O21: =(F21 + G21 + H21) / I21 -> 0.29713518 | P21: =F21 + G21 + H21 -> 3319
A22: P066 | B22: Twitter | C22: 45499 | D22: Carousel | E22: Check out our latest carousel on twitter! | F22: 432 | G22: 171 | H22: 280 | I22: 3024 | J22: 2285 | K22: 184 | L22: #ThirstyForMore | O22: =(F22 + G22 + H22) / I22 -> 0.29199735 | P22: =F22 + G22 + H22 -> 883
A23: P183 | B23: Instagram | C23: 45643 | D23: Story | E23: Check out our latest story on instagram! | F23: 360 | G23: 590 | H23: 393 | I23: 4680 | J23: 4322 | K23: 208 | L23: #LiveForNow | O23: =(F23 + G23 + H23) / I23 -> 0.28696581 | P23: =F23 + G23 + H23 -> 1343
A24: P031 | B24: Instagram | C24: 45642 | D24: Text | E24: Check out our latest text on instagram! | F24: 438 | G24: 153 | H24: 275 | I24: 3066 | J24: 2701 | K24: 282 | L24: #PepsiCoRefresh | O24: =(F24 + G24 + H24) / I24 -> 0.28245271 | P24: =F24 + G24 + H24 -> 866
A25: P093 | B25: Instagram | C25: 45637 | D25: Video | E25: Check out our latest video on instagram! | F25: 1431 | G25: 951 | H25: 26 | I25: 8586 | J25: 8396 | K25: 150 | L25: #ThirstyForMore | O25: =(F25 + G25 + H25) / I25 -> 0.28045656 | P25: =F25 + G25 + H25 -> 2408
... A45: P159 | B45: Facebook | C45: 45621 | D45: Story | E45: Check out our latest story on facebook! | F45: 2120 | G45: 158 | H45: 488 | I45: 12720 | J45: 12085 | K45: 17 | L45: #LiveForNow | O45: =(F45 + G45 + H45) / I45 -> 0.21745283 | P45: =F45 + G45 + H45 -> 2766
A46: P146 | B46: YouTube | C46: 45448 | D46: Reel | E46: Check out our latest reel on youtube! | F46: 3065 | G46: 772 | H46: 142 | I46: 18390 | J46: 17875 | K46: 200 | L46: #ThirstyForMore | M46: #AnytimeIsPepsiTime | O46: =(F46 + G46 + H46) / I46 -> 0.21636759 | P46: =F46 + G46 + H46 -> 3979
A47: P029 | B47: Instagram | C47: 45688 | D47: Carousel | E47: Check out our latest carousel on instagram! | F47: 2566 | G47: 118 | H47: 37 | I47: 12830 | J47: 12264 | K47: 221 | L47: #LiveForNow | O47: =(F47 + G47 + H47) / I47 -> 0.21208106 | P47: =F47 + G47 + H47 -> 2721
A48: P137 | B48: Facebook | C48: 45504 | D48: Video | E48: Check out our latest video on facebook! | F48: 3008 | G48: 94 | H48: 37 | I48: 15040 | J48: 14639 | K48: 277 | L48: #LiveForNow | O48: =(F48 + G48 + H48) / I48 -> 0.20871011 | P48: =F48 + G48 + H48 -> 3139
A49: P087 | B49: Twitter | C49: 45449 | D49: Video | E49: Check out our latest video on twitter! | F49: 1436 | G49: 765 | H49: 496 | I49: 12924 | J49: 12701 | K49: 197 | L49: #LiveForNow | O49: =(F49 + G49 + H49) / I49 -> 0.20868152 | P49: =F49 + G49 + H49 -> 2697
A50: P271 | B50: Instagram | C50: 45582 | D50: Video | E50: Check out our latest video on instagram! | F50: 3575 | G50: 749 | H50: 111 | I50: 21450 | J50: 20785 | K50: 195 | L50: #ThirstyForMore | O50: =(F50 + G50 + H50) / I50 -> 0.20675991 | P50: =F50 + G50 + H50 -> 4435
A51: P077 | B51: Facebook | C51: 45720 | D51: Story | E51: Check out our latest story on facebook! | F51: 1249 | G51: 116 | H51: 420 | I51: 8743 | J51: 8538 | K51: 63 | L51: #PepsiCoRefresh | O51: =(F51 + G51 + H51) / I51 -> 0.20416333 | P51: =F51 + G51 + H51 -> 1785
A52: P136 | B52: Instagram | C52: 45484 | D52: Text | E52: Check out our latest text on instagram! | F52: 3134 | G52: 888 | H52: 444 | I52: 21938 | J52: 21337 | K52: 130 | L52: #ThirstyForMore | O52: =(F52 + G52 + H52) / I52 -> 0.20357371 | P52: =F52 + G52 + H52 -> 4466
A53: P258 | B53: Instagram | C53: 45509 | D53: Story | E53: Check out our latest story on instagram! | F53: 3601 | G53: 695 | H53: 75 | I53: 21606 | J53: 21454 | K53: 172 | L53: #ThirstyForMore | O53: =(F53 + G53 + H53) / I53 -> 0.20230492 | P53: =F53 + G53 + H53 -> 4371
A54: P276 | B54: Twitter | C54: 45450 | D54: Carousel | E54: Check out our latest carousel on twitter! | F54: 1556 | G54: 195 | H54: 131 | I54: 9336 | J54: 8875 | K54: 137 | L54: #PepsiCoRefresh | O54: =(F54 + G54 + H54) / I54 -> 0.20158526 | P54: =F54 + G54 + H54 -> 1882
A55: P148 | B55: Instagram | C55: 45762 | D55: Video | E55: Check out our latest video on instagram! | F55: 4133 | G55: 466 | H55: 327 | I55: 24798 | J55: 24620 | K55: 176 | L55: #ThirstyForMore | O55: =(F55 + G55 + H55) / I55 -> 0.19864505 | P55: =F55 + G55 + H55 -> 4926
A56: P198 | B56: Twitter | C56: 45549 | D56: Image | E56: Check out our latest image on twitter! | F56: 1048 | G56: 374 | H56: 450 | I56: 9432 | J56: 8882 | K56: 158 | L56: #PepsiCoRefresh | O56: =(F56 + G56 + H56) / I56 -> 0.19847328 | P56: =F56 + G56 + H56 -> 1872
A57: P152 | B57: Facebook | C57: 45769 | D57: Image | E57: Check out our latest image on facebook! | F57: 4804 | G57: 550 | H57: 270 | I57: 28824 | J57: 28370 | K57: 47 | L57: #ThirstyForMore | O57: =(F57 + G57 + H57) / I57 -> 0.19511518 | P57: =F57 + G57 + H57 -> 5624
A58: P286 | B58: YouTube | C58: 45560 | D58: Video | E58: Check out our latest video on youtube! | F58: 3389 | G58: 344 | H58: 229 | I58: 20334 | J58: 19443 | K58: 228 | L58: #LiveForNow | O58: =(F58 + G58 + H58) / I58 -> 0.19484607 | P58: =F58 + G58 + H58 -> 3962
... A80: P047 | B80: Twitter | C80: 45712 | D80: Carousel | E80: Check out our latest carousel on twitter! | F80: 2704 | G80: 752 | H80: 153 | I80: 21632 | J80: 20792 | K80: 127 | L80: #LiveForNow | O80: =(F80 + G80 + H80) / I80 -> 0.16683617 | P80: =F80 + G80 + H80 -> 3609
...

Sheet Task3-1 Pivot Table
A1: Platform | B1: SUM of Total Engagement = Likes + Shares + Comments
A2: Facebook | B2: 305242
A3: Instagram | B3: 263579
A4: Twitter | B4: 256005
A5: YouTube | B5: 212941
A6: Grand Total | B6: 1037767
D26: Insights:Based on the pie chart visualization of total engagement (likes + shares + comments), Facebook emerged as the top-performing platform with over 305,000 total engagements, followed by Instagram (263,579) and Twitter (256,005). YouTube had the lowest total engagement at 212,941. This suggests that Facebook is highly effective in driving interactions and user engagement, making it a strong platform for brand visibility and community engagement efforts. However, Instagram and Twitter are not far behind and also contribute significantly to overall engagement.

Sheet Task3-2 
A1: Week_Start_Date | B1: Platform | C1: New_Followers | D1: Unfollows | E1: Total_Followers | F1: Engagement_Rate | G1: Ad_Spend | H1: Growth Rate % | I1: Engagement per Rupee
A2: 45446 | B2: Instagram | C2: 1135 | D2: 88 | E2: 344084 | F2: 8.06 | G2: 5904 | H2: =((C2 - D2) / E2) * 100 -> 0.30428616 | I2: =F2 / G2 -> 0.0013651762
A3: 45446 | B3: Facebook | C3: 1312 | D3: 310 | E3: 42654 | F3: 4.98 | G3: 9566 | H3: =((C3 - D3) / E3) * 100 -> 2.3491349 | I3: =F3 / G3 -> 0.00052059377
A4: 45446 | B4: Twitter | C4: 584 | D4: 169 | E4: 146834 | F4: 8.31 | G4: 26752 | H4: =((C4 - D4) / E4) * 100 -> 0.28263209 | I4: =F4 / G4 -> 0.00031063098
A5: 45446 | B5: YouTube | C5: 1535 | D5: 445 | E5: 395536 | F5: 4.11 | G5: 30671 | H5: =((C5 - D5) / E5) * 100 -> 0.27557542 | I5: =F5 / G5 -> 0.0001340028
A6: 45453 | B6: Instagram | C6: 656 | D6: 139 | E6: 49157 | F6: 9.05 | G6: 9920 | H6: =((C6 - D6) / E6) * 100 -> 1.0517322 | I6: =F6 / G6 -> 0.00091229839
A7: 45453 | B7: Facebook | C7: 1697 | D7: 414 | E7: 316555 | F7: 2.37 | G7: 7924 | H7: =((C7 - D7) / E7) * 100 -> 0.40530082 | I7: =F7 / G7 -> 0.00029909137
A8: 45453 | B8: Twitter | C8: 436 | D8: 250 | E8: 254347 | F8: 4.01 | G8: 8912 | H8: =((C8 - D8) / E8) * 100 -> 0.073128443 | I8: =F8 / G8 -> 0.00044995512
A9: 45453 | B9: YouTube | C9: 1197 | D9: 203 | E9: 413878 | F9: 3.16 | G9: 21205 | H9: =((C9 - D9) / E9) * 100 -> 0.24016739 | I9: =F9 / G9 -> 0.00014902146
A10: 45460 | B10: Instagram | C10: 1048 | D10: 155 | E10: 456946 | F10: 2.46 | G10: 11329 | H10: =((C10 - D10) / E10) * 100 -> 0.19542791 | I10: =F10 / G10 -> 0.00021714185
A11: 45460 | B11: Facebook | C11: 1753 | D11: 371 | E11: 169496 | F11: 8.11 | G11: 46670 | H11: =((C11 - D11) / E11) * 100 -> 0.81535847 | I11: =F11 / G11 -> 0.0001737733
A12: 45460 | B12: Twitter | C12: 1335 | D12: 40 | E12: 122732 | F12: 8.19 | G12: 22482 | H12: =((C12 - D12) / E12) * 100 -> 1.0551445 | I12: =F12 / G12 -> 0.00036429143
A13: 45460 | B13: YouTube | C13: 403 | D13: 66 | E13: 382851 | F13: 3.49 | G13: 24313 | H13: =((C13 - D13) / E13) * 100 -> 0.0880238 | I13: =F13 / G13 -> 0.00014354461
... A201: 45789 | B201: YouTube | C201: 119 | D201: 456 | E201: 82558 | F201: 6.81 | G201: 12174 | H201: =((C201 - D201) / E201) * 100 -> -0.40819787 | I201: =F201 / G201 -> 0.00055938886

Sheet Task3-2 Pivot Table
A1: Platform | B1: AVERAGE of Growth Rate % | C1: AVERAGE of Engagement per Rupee
A3: Facebook | B3: 0.54649907 | C3: 0.00030899518
A4: Instagram | B4: 0.57625321 | C4: 0.00053203004
A5: Twitter | B5: 0.92800257 | C5: 0.00044517296
A6: YouTube | B6: 0.90210666 | C6: 0.0003278738
A7: Grand Total | B7: 0.73821538 | C7: 0.000403518

Sheet Task3-3 Pivot Table
A1: Campaign Name | B1: Platform | C1: Budget Split | E1: Platform | F1: Total Budget
A2: SummerSplash | B2: Instagram | C2: 75000 | E2: Instagram | F2: =SUMIF(B$2:B$10, E2, C$2:C$10) -> 285000
A3: SummerSplash | B3: Facebook | C3: 75000 | E3: Facebook | F3: =SUMIF(B$2:B$10, E3, C$2:C$10) -> 135000
A4: FestiveRadiance | B4: Instagram | C4: 100000 | E4: Twitter | F4: =SUMIF(B$2:B$10, E4, C$2:C$10) -> 110000
A5: FestiveRadiance | B5: YouTube | C5: 100000 | E5: YouTube | F5: =SUMIF(B$2:B$10, E5, C$2:C$10) -> 100000
A6: NewYearRefresh | B6: Instagram | C6: 60000
A7: NewYearRefresh | B7: Facebook | C7: 60000
A8: NewYearRefresh | B8: Twitter | C8: 60000
A9: DailyWellness | B9: Instagram | C9: 50000
A10: DailyWellness | B10: Twitter | C10: 50000
G36: Insight: Instagram received the largest portion of the budget (₹285,000), indicating it's a primary focus platform. Twitter and Facebook followed. Based on this allocation, Instagram should remain a core platform while others can be optimized based on performance.

Sheet Task4 Hashtag & Content Strateg
A1: Post Id | B1: Platform | C1: Date | D1: Content Type | E1: Post Text | F1: Likes | G1: Shares | H1: Comments | I1: Impressions | J1: Reach | K1: Clicks | L1: Hashtags Used | O1: Hashtags Summary | P1: Total Engagement
A2: P001 | B2: Twitter | C2: 45649 | D2: Reel | E2: Check out our latest reel on twitter! | F2: 1461 | G2: 184 | H2: 344 | I2: 21915 | J2: 21675 | K2: 15 | L2: #LiveForNow | M2: #AnytimeIsPepsiTime | O2: =L2&M2&N2 -> #LiveForNow#AnytimeIsPepsiTime | P2: =F2 + H2 -> 1805
A3: P002 | B3: Twitter | C3: 45750 | D3: Text | E3: Check out our latest text on twitter! | F3: 4054 | G3: 389 | H3: 493 | I3: 64864 | J3: 64383 | K3: 117 | L3: #PepsiCoRefresh | M3: #BetterWithPepsi | O3: =L3&M3&N3 -> #PepsiCoRefresh#BetterWithPepsi | P3: =F3 + H3 -> 4547
A4: P003 | B4: YouTube | C4: 45789 | D4: Reel | E4: Check out our latest reel on youtube! | F4: 2795 | G4: 105 | H4: 49 | I4: 53105 | J4: 52307 | K4: 204 | L4: #PepsiCoRefresh | O4: =L4&M4&N4 -> #PepsiCoRefresh | P4: =F4 + H4 -> 2844
A5: P004 | B5: Instagram | C5: 45516 | D5: Story | E5: Check out our latest story on instagram! | F5: 2404 | G5: 363 | H5: 138 | I5: 19232 | J5: 18636 | K5: 128 | L5: #ThirstyForMore | O5: =L5&M5&N5 -> #ThirstyForMore | P5: =F5 + H5 -> 2542
A6: P005 | B6: YouTube | C6: 45469 | D6: Reel | E6: Check out our latest reel on youtube! | F6: 3557 | G6: 687 | H6: 424 | I6: 71140 | J6: 70701 | K6: 224 | L6: #ThirstyForMore | M6: #PepsiCoRefresh | O6: =L6&M6&N6 -> #ThirstyForMore#PepsiCoRefresh | P6: =F6 + H6 -> 3981
A7: P006 | B7: Facebook | C7: 45596 | D7: Carousel | E7: Check out our latest carousel on facebook! | F7: 2945 | G7: 930 | H7: 355 | I7: 23560 | J7: 23275 | K7: 256 | L7: #PepsiCoRefresh | O7: =L7&M7&N7 -> #PepsiCoRefresh | P7: =F7 + H7 -> 3300
A8: P007 | B8: Twitter | C8: 45467 | D8: Carousel | E8: Check out our latest carousel on twitter! | F8: 3860 | G8: 201 | H8: 279 | I8: 61760 | J8: 61660 | K8: 235 | L8: #PepsiCoRefresh | O8: =L8&M8&N8 -> #PepsiCoRefresh | P8: =F8 + H8 -> 4139
A9: P008 | B9: YouTube | C9: 45486 | D9: Image | E9: Check out our latest image on youtube! | F9: 3929 | G9: 262 | H9: 278 | I9: 43219 | J9: 42841 | K9: 39 | L9: #ThirstyForMore | O9: =L9&M9&N9 -> #ThirstyForMore | P9: =F9 + H9 -> 4207
A10: P009 | B10: Facebook | C10: 45534 | D10: Text | E10: Check out our latest text on facebook! | F10: 3784 | G10: 808 | H10: 404 | I10: 56760 | J10: 56343 | K10: 131 | L10: #PepsiCoRefresh | O10: =L10&M10&N10 -> #PepsiCoRefresh | P10: =F10 + H10 -> 4188
A11: P010 | B11: Facebook | C11: 45727 | D11: Image | E11: Check out our latest image on facebook! | F11: 4241 | G11: 902 | H11: 47 | I11: 72097 | J11: 71598 | K11: 167 | L11: #PepsiCoRefresh | O11: =L11&M11&N11 -> #PepsiCoRefresh | P11: =F11 + H11 -> 4288
A12: P011 | B12: Instagram | C12: 45690 | D12: Story | E12: Check out our latest story on instagram! | F12: 1792 | G12: 614 | H12: 497 | I12: 25088 | J12: 24675 | K12: 65 | L12: #LiveForNow | O12: =L12&M12&N12 -> #LiveForNow | P12: =F12 + H12 -> 2289
A13: P012 | B13: Facebook | C13: 45494 | D13: Reel | E13: Check out our latest reel on facebook! | F13: 1946 | G13: 686 | H13: 377 | I13: 23352 | J13: 22982 | K13: 213 | L13: #LiveForNow | O13: =L13&M13&N13 -> #LiveForNow | P13: =F13 + H13 -> 2323
A14: P013 | B14: YouTube | C14: 45614 | D14: Carousel | E14: Check out our latest carousel on youtube! | F14: 1171 | G14: 286 | H14: 231 | I14: 22249 | J14: 21282 | K14: 114 | L14: #ThirstyForMore | O14: =L14&M14&N14 -> #ThirstyForMore | P14: =F14 + H14 -> 1402
A15: P014 | B15: Facebook | C15: 45704 | D15: Story | E15: Check out our latest story on facebook! | F15: 4242 | G15: 555 | H15: 131 | I15: 33936 | J15: 33802 | K15: 265 | L15: #LiveForNow | O15: =L15&M15&N15 -> #LiveForNow | P15: =F15 + H15 -> 4373
A16: P015 | B16: Facebook | C16: 45589 | D16: Video | E16: Check out our latest video on facebook! | F16: 3888 | G16: 604 | H16: 128 | I16: 77760 | J16: 77167 | K16: 20 | L16: #LiveForNow | O16: =L16&M16&N16 -> #LiveForNow | P16: =F16 + H16 -> 4016
A17: P016 | B17: Facebook | C17: 45530 | D17: Text | E17: Check out our latest text on facebook! | F17: 3452 | G17: 377 | H17: 360 | I17: 55232 | J17: 55075 | K17: 87 | L17: #LiveForNow | O17: =L17&M17&N17 -> #LiveForNow | P17: =F17 + H17 -> 3812
A18: P017 | B18: Facebook | C18: 45782 | D18: Text | E18: Check out our latest text on facebook! | F18: 4441 | G18: 511 | H18: 70 | I18: 53292 | J18: 53082 | K18: 159 | L18: #ThirstyForMore | O18: =L18&M18&N18 -> #ThirstyForMore | P18: =F18 + H18 -> 4511
... A23: P022 | B23: Facebook | C23: 45715 | D23: Text | E23: Check out our latest text on facebook! | F23: 1570 | G23: 187 | H23: 260 | I23: 25120 | J23: 24613 | K23: 133 | L23: #PepsiCoRefresh | O23: =L23&M23&N23 -> #PepsiCoRefresh | P23: =F23 + H23 -> 1830
A24: P023 | B24: Facebook | C24: 45602 | D24: Video | E24: Check out our latest video on facebook! | F24: 1606 | G24: 547 | H24: 316 | I24: 32120 | J24: 31736 | K24: 225 | L24: #PepsiCoRefresh | M24: #AnytimeIsPepsiTime | O24: =L24&M24&N24 -> #PepsiCoRefresh#AnytimeIsPepsiTime | P24: =F24 + H24 -> 1922
A25: P024 | B25: Facebook | C25: 45680 | D25: Video | E25: Check out our latest video on facebook! | F25: 3961 | G25: 761 | H25: 131 | I25: 67337 | J25: 66615 | K25: 161 | L25: #LiveForNow | O25: =L25&M25&N25 -> #LiveForNow | P25: =F25 + H25 -> 4092
A26: P025 | B26: Twitter | C26: 45757 | D26: Carousel | E26: Check out our latest carousel on twitter! | F26: 3128 | G26: 211 | H26: 197 | I26: 59432 | J26: 59182 | K26: 238 | L26: #ThirstyForMore | O26: =L26&M26&N26 -> #ThirstyForMore | P26: =F26 + H26 -> 3325
A27: P026 | B27: YouTube | C27: 45752 | D27: Reel | E27: Check out our latest reel on youtube! | F27: 3009 | G27: 413 | H27: 358 | I27: 42126 | J27: 41309 | K27: 211 | L27: #LiveForNow | O27: =L27&M27&N27 -> #LiveForNow | P27: =F27 + H27 -> 3367
A28: P027 | B28: YouTube | C28: 45552 | D28: Text | E28: Check out our latest text on youtube! | F28: 2076 | G28: 195 | H28: 104 | I28: 33216 | J28: 32244 | K28: 51 | L28: #LiveForNow | O28: =L28&M28&N28 -> #LiveForNow | P28: =F28 + H28 -> 2180
A29: P028 | B29: Instagram | C29: 45720 | D29: Video | E29: Check out our latest video on instagram! | F29: 432 | G29: 624 | H29: 123 | I29: 6912 | J29: 6259 | K29: 79 | L29: #LiveForNow | O29: =L29&M29&N29 -> #LiveForNow | P29: =F29 + H29 -> 555
A30: P029 | B30: Instagram | C30: 45688 | D30: Carousel | E30: Check out our latest carousel on instagram! | F30: 2566 | G30: 118 | H30: 37 | I30: 12830 | J30: 12264 | K30: 221 | L30: #LiveForNow | O30: =L30&M30&N30 -> #LiveForNow | P30: =F30 + H30 -> 2603
A31: P030 | B31: Instagram | C31: 45713 | D31: Video | E31: Check out our latest video on instagram! | F31: 3095 | G31: 39 | H31: 78 | I31: 55710 | J31: 54808 | K31: 93 | L31: #ThirstyForMore | O31: =L31&M31&N31 -> #ThirstyForMore | P31: =F31 + H31 -> 3173
A32: P031 | B32: Instagram | C32: 45642 | D32: Text | E32: Check out our latest text on instagram! | F32: 438 | G32: 153 | H32: 275 | I32: 3066 | J32: 2701 | K32: 282 | L32: #PepsiCoRefresh | O32: =L32&M32&N32 -> #PepsiCoRefresh | P32: =F32 + H32 -> 713
A33: P032 | B33: Twitter | C33: 45504 | D33: Carousel | E33: Check out our latest carousel on twitter! | F33: 2278 | G33: 10 | H33: 321 | I33: 13668 | J33: 12676 | K33: 275 | L33: #ThirstyForMore | O33: =L33&M33&N33 -> #ThirstyForMore | P33: =F33 + H33 -> 2599
A34: P033 | B34: Facebook | C34: 45525 | D34: Image | E34: Check out our latest image on facebook! | F34: 1407 | G34: 400 | H34: 351 | I34: 16884 | J34: 15954 | K34: 113 | L34: #PepsiCoRefresh | O34: =L34&M34&N34 -> #PepsiCoRefresh | P34: =F34 + H34 -> 1758
A35: P034 | B35: Facebook | C35: 45742 | D35: Text | E35: Check out our latest text on facebook! | F35: 1652 | G35: 89 | H35: 357 | I35: 29736 | J35: 28771 | K35: 215 | L35: #PepsiCoRefresh | O35: =L35&M35&N35 -> #PepsiCoRefresh | P35: =F35 + H35 -> 2009
A36: P035 | B36: Instagram | C36: 45626 | D36: Video | E36: Check out our latest video on instagram! | F36: 3775 | G36: 16 | H36: 239 | I36: 33975 | J36: 33310 | K36: 271 | L36: #LiveForNow | O36: =L36&M36&N36 -> #LiveForNow | P36: =F36 + H36 -> 4014
... A53: P052 | B53: Facebook | C53: 45660 | D53: Image | E53: Check out our latest image on facebook! | F53: 947 | G53: 338 | H53: 350 | I53: 10417 | J53: 9730 | K53: 34 | L53: #PepsiCoRefresh | O53: =L53&M53&N53 -> #PepsiCoRefresh | P53: =F53 + H53 -> 1297
A54: P053 | B54: YouTube | C54: 45712 | D54: Carousel | E54: Check out our latest carousel on youtube! | F54: 804 | G54: 639 | H54: 43 | I54: 4020 | J54: 3144 | K54: 11 | L54: #ThirstyForMore | M54: #BetterWithPepsi | O54: =L54&M54&N54 -> #ThirstyForMore#BetterWithPepsi | P54: =F54 + H54 -> 847
A55: P054 | B55: YouTube | C55: 45729 | D55: Carousel | E55: Check out our latest carousel on youtube! | F55: 1686 | G55: 904 | H55: 472 | I55: 18546 | J55: 18171 | K55: 52 | L55: #LiveForNow | O55: =L55&M55&N55 -> #LiveForNow | P55: =F55 + H55 -> 2158
A56: P055 | B56: Facebook | C56: 45460 | D56: Image | E56: Check out our latest image on facebook! | F56: 1226 | G56: 119 | H56: 7 | I56: 14712 | J56: 14049 | K56: 123 | L56: #ThirstyForMore | O56: =L56&M56&N56 -> #ThirstyForMore | P56: =F56 + H56 -> 1233
A57: P056 | B57: Facebook | C57: 45644 | D57: Carousel | E57: Check out our latest carousel on facebook! | F57: 2946 | G57: 498 | H57: 367 | I57: 29460 | J57: 28527 | K57: 60 | L57: #LiveForNow | O57: =L57&M57&N57 -> #LiveForNow | P57: =F57 + H57 -> 3313
A58: P057 | B58: Twitter | C58: 45586 | D58: Video | E58: Check out our latest video on twitter! | F58: 2825 | G58: 535 | H58: 295 | I58: 45200 | J58: 44739 | K58: 169 | L58: #PepsiCoRefresh | O58: =L58&M58&N58 -> #PepsiCoRefresh | P58: =F58 + H58 -> 3120
A59: P058 | B59: Instagram | C59: 45762 | D59: Reel | E59: Check out our latest reel on instagram! | F59: 103 | G59: 770 | H59: 19 | I59: 1030 | J59: 410 | K59: 262 | L59: #PepsiCoRefresh | O59: =L59&M59&N59 -> #PepsiCoRefresh | P59: =F59 + H59 -> 122
A60: P059 | B60: Instagram | C60: 45465 | D60: Text | E60: Check out our latest text on instagram! | F60: 2180 | G60: 263 | H60: 387 | I60: 30520 | J60: 30059 | K60: 174 | L60: #ThirstyForMore | O60: =L60&M60&N60 -> #ThirstyForMore | P60: =F60 + H60 -> 2567
...

Sheet Task4 Pivot Table1
A1: AVERAGE of Total Engagement | B1: Content Type
A2: Platform | B2: Carousel | C2: Image | D2: Reel | E2: Story | F2: Text | G2: Video | H2: Grand Total
A3: Facebook | B3: 3504.6429 | C3: 3123.88 | D3: 3611 | E3: 2966.1818 | F3: 2718.4615 | G3: 3467.7778 | H3: 3205.5542
A4: Instagram | B4: 2814 | C4: 3685.7 | D4: 2733.3846 | E4: 2735 | F4: 2751.3 | G4: 2324.8333 | H4: 2811.8354
A5: Twitter | B5: 3073.8824 | C5: 2572.9474 | D5: 2631.0909 | E5: 2610.2222 | F5: 3255.3636 | G5: 2741 | H5: 2813.6329
A6: YouTube | B6: 2486.1818 | C6: 2886.6667 | D6: 2922.3333 | E6: 3775.5556 | F6: 3514.875 | G6: 3387.4 | H6: 3124.8983
A7: Grand Total | B7: 2991.6441 | C7: 3013.0159 | D7: 2963.0851 | E7: 2969.4565 | F7: 3018.5952 | G7: 2927.3023 | H7: 2982.8067
D33: Recommended Content Types by Platform 1.Facebook Top performer: Reels (3611) and Videos (3467.78) Recommendation: Focus on short-form video content like Reels and Videos. Carousels also perform well and can be used to complement these formats. 2.Instagram Top performer: Images (3685.70) followed by Text (2751.3) and Carousels (2814.00) Recommendation: Prioritize high-quality static images and carousel posts with creative storytelling. Avoid video-heavy strategy here. 3.Twitter Top performer: Text (3255.36) and Carousel (3073.88) Recommendation: Use text-driven tweets with engaging captions, and use carousels for campaign messaging and visual storytelling. 4.YouTube Top performer: Stories (3775.56) and Text (3514.88) Recommendation: Focus on YouTube Shorts (story-like) and strong captions/descriptions in text format. Support with videos, which also perform well.

Sheet Task5-1 Pivot Table 1
B1: Campaign_Period | C1: Values
B2: After Campaign | G2: Before Campaign | L2: During Campaign | Q2: Grand Total
A3: Campaign_Name | B3: SUM of Likes | C3: SUM of Shares | D3: SUM of Impressions | E3: SUM of Comments | F3: SUM of Clicks | G3: SUM of Likes | H3: SUM of Shares | I3: SUM of Impressions | J3: SUM of Comments | K3: SUM of Clicks | L3: SUM of Likes | M3: SUM of Shares | N3: SUM of Impressions | O3: SUM of Comments | P3: SUM of Clicks | Q3: SUM of Likes | R3: SUM of Shares | S3: SUM of Impressions | T3: SUM of Comments | U3: SUM of Clicks | V3: Likes Uplift % | W3: Shares Uplift% | X3: Impressions Uplift% | Y3: Comments Uplift% | Z3: Clicks Uplift%
B4: 146200 | C4: 25284 | D4: 1794968 | E4: 13105 | F4: 8131 | G4: 3960 | H4: 266 | I4: 35640 | J4: 8 | K4: 208 | Q4: 150160 | R4: 25550 | S4: 1830608 | T4: 13113 | U4: 8339
A5: DailyWellness | G5: 5189 | H5: 1144 | I5: 76007 | J5: 631 | K5: 386 | L5: 182720 | M5: 33716 | N5: 2388857 | O5: 17083 | P5: 10303 | Q5: 187909 | R5: 34860 | S5: 2464864 | T5: 17714 | U5: 10689 | V5: =IF(G5=0, 0, (M5 - G5) / G5 * 100) -> 549.75911 | W5: =IF(H5=0, 0, (N5 - H5) / H5 * 100) -> 208716.17 | X5: =IF(I5=0, 0, (O5 - I5) / I5 * 100) -> -77.524439 | Y5: =IF(J5=0, 0, (P5 - J5) / J5 * 100) -> 1532.8051 | Z5: =IF(K5=0, 0, (Q5 - K5) / K5 * 100) -> 48581.088
A6: FestiveRadiance | G6: 6299 | H6: 1060 | I6: 77626 | J6: 802 | K6: 454 | L6: 153484 | M6: 25493 | N6: 1908730 | O6: 14601 | P6: 9418 | Q6: 159783 | R6: 26553 | S6: 1986356 | T6: 15403 | U6: 9872 | V6: =IF(G6=0, 0, (M6 - G6) / G6 * 100) -> 304.71503 | W6: =IF(H6=0, 0, (N6 - H6) / H6 * 100) -> 179968.87 | X6: =IF(I6=0, 0, (O6 - I6) / I6 * 100) -> -81.19058 | Y6: =IF(J6=0, 0, (P6 - J6) / J6 * 100) -> 1074.3142 | Z6: =IF(K6=0, 0, (Q6 - K6) / K6 * 100) -> 35094.493
A7: NewYearRefresh | G7: 6890 | H7: 2024 | I7: 103622 | J7: 1032 | K7: 439 | L7: 176456 | M7: 30885 | N7: 2162431 | O7: 15534 | P7: 9593 | Q7: 183346 | R7: 32909 | S7: 2266053 | T7: 16566 | U7: 10032 | V7: =IF(G7=0, 0, (M7 - G7) / G7 * 100) -> 348.25835 | W7: =IF(H7=0, 0, (N7 - H7) / H7 * 100) -> 106739.48 | X7: =IF(I7=0, 0, (O7 - I7) / I7 * 100) -> -85.008975 | Y7: =IF(J7=0, 0, (P7 - J7) / J7 * 100) -> 829.55426 | Z7: =IF(K7=0, 0, (Q7 - K7) / K7 * 100) -> 41664.465
A8: SummerSplash | G8: 4494 | H8: 717 | I8: 62916 | J8: 45 | K8: 191 | L8: 134299 | M8: 22336 | N8: 1783356 | O8: 12010 | P8: 6243 | Q8: 138793 | R8: 23053 | S8: 1846272 | T8: 12055 | U8: 6434 | V8: =IF(G8=0, 0, (M8 - G8) / G8 * 100) -> 397.01825 | W8: =IF(H8=0, 0, (N8 - H8) / H8 * 100) -> 248624.69 | X8: =IF(I8=0, 0, (O8 - I8) / I8 * 100) -> -80.911056 | Y8: =IF(J8=0, 0, (P8 - J8) / J8 * 100) -> 13773.333 | Z8: =IF(K8=0, 0, (Q8 - K8) / K8 * 100) -> 72566.492
A9: Grand Total | B9: 146200 | C9: 25284 | D9: 1794968 | E9: 13105 | F9: 8131 | G9: 26832 | H9: 5211 | I9: 355811 | J9: 2518 | K9: 1678 | L9: 646959 | M9: 112430 | N9: 8243374 | O9: 59228 | P9: 35557 | Q9: 819991 | R9: 142925 | S9: 10394153 | T9: 74851 | U9: 45366 | V9: =IF(G9=0, 0, (M9 - G9) / G9 * 100) -> 319.01461 | W9: =IF(H9=0, 0, (N9 - H9) / H9 * 100) -> 158091.79 | X9: =IF(I9=0, 0, (O9 - I9) / I9 * 100) -> -83.354084 | Y9: =IF(J9=0, 0, (P9 - J9) / J9 * 100) -> 1312.1128 | Z9: =IF(K9=0, 0, (Q9 - K9) / K9 * 100) -> 48767.163
A34: All campaigns showed huge increases in engagement during their periods, especially DailyWellness with the highest uplift in Likes and Shares. Impressions dropped, indicating a smaller but more engaged audience. Clicks and Comments also rose significantly, with SummerSplash leading in clicks. DailyWellness had the best ROI, while NewYearRefresh lagged slightly. Overall, campaigns boosted quality engagement despite fewer impressions, suggesting a need to focus on optimizing reach while maintaining strong interaction.

Sheet Task4 Pivvot Table2
A1: Hashtags Summary | B1: AVERAGE of Total Engagement
A2: #LiveForNow | B2: 2956.2842
A3: #LiveForNow#AnytimeIsPepsiTime | B3: 2631
A4: #LiveForNow#AnytimeIsPepsiTime#ThirstyForMore | B4: 1608
A5: #LiveForNow#PepsiCoRefresh#AnytimeIsPepsiTime | B5: 1517.3333
A6: #LiveForNow#SmoothLikeNitroPepsi | B6: 2177
A7: #LiveForNow#ThirstyForMore#BetterWithPepsi | B7: 3968
A8: #PepsiCoRefresh | B8: 2919.6067
A9: #PepsiCoRefresh#AnytimeIsPepsiTime | B9: 3129.6
A10: #PepsiCoRefresh#BetterWithPepsi | B10: 4547
A11: #PepsiCoRefresh#SmoothLikeNitroPepsi | B11: 4034.3333
A12: #PepsiCoRefresh#ThirstyForMore#BetterWithPepsi | B12: 4545
A13: #ThirstyForMore | B13: 3076.5795
... A20: Grand Total | B20: 2982.8067
A24: Hashtags Summary | B24: COUNTA of Hashtags Summary
A25: #LiveForNow | B25: 95
A26: #LiveForNow#AnytimeIsPepsiTime | B26: 2
A27: #LiveForNow#AnytimeIsPepsiTime#ThirstyForMore | B27: 1
A28: #LiveForNow#PepsiCoRefresh#AnytimeIsPepsiTime | B28: 3
A29: #LiveForNow#SmoothLikeNitroPepsi | B29: 1
A30: #LiveForNow#ThirstyForMore#BetterWithPepsi | B30: 1
A31: #PepsiCoRefresh | B31: 89
A32: #PepsiCoRefresh#AnytimeIsPepsiTime | B32: 5
A33: #PepsiCoRefresh#BetterWithPepsi | B33: 1
A34: #PepsiCoRefresh#SmoothLikeNitroPepsi | B34: 3
A35: #PepsiCoRefresh#ThirstyForMore#BetterWithPepsi | B35: 2
A36: #ThirstyForMore | B36: 88
... A43: Grand Total | B43: 300
B47: Most frequently used hashtags (based on COUNTA of Hashtags Summary) are: #LiveForNow → 95 uses #PepsiCoRefresh → 89 uses #ThirstyForMore → 88 uses These three are clearly the top hashtags, each used far more often than the rest, which are combinations or less frequent tags.

Sheet Task 5-1  Campaign Effectivenes
A1: Post ID | B1: Platform | C1: Date | D1: Content Type | E1: Post Text | F1: Likes | G1: Shares | H1: Comments | I1: Impressions | J1: Reach | K1: Clicks | L1: Hashtags Used | O1: Campaign_Name | P1: Campaign_Start_Date | Q1: Campaign_End_Date | R1: Campaign_Period | S1: Total Engagement = Likes + Shares + Comments | T1: Engagement Rate
A2: P001 | B2: Twitter | C2: 45649 | D2: Reel | E2: Check out our latest reel on twitter! | F2: 1461 | G2: 184 | H2: 344 | I2: 21915 | J2: 21675 | K2: 15 | L2: #LiveForNow | M2: #AnytimeIsPepsiTime | O2: SummerSplash | P2: =IFS( O2="SummerSplash", DATE(2024,6,15), O2="FestiveRadiance", DATE(2024,10,1), O2="NewYearRefresh", DATE(2024,12,25), O2="DailyWellness", DATE(2025,3,1) ) -> 45458 | Q2: =IFS( O2="SummerSplash", DATE(2024,7,15), O2="FestiveRadiance", DATE(2024,10,31), O2="NewYearRefresh", DATE(2025,1,10), O2="DailyWellness", DATE(2025,3,31) ) -> 45488 | R2: =IF(C2 < N2, "Before Campaign", IF(AND(C2 >= N2, C2 <= O2), "During Campaign", "After Campaign")) -> During Campaign | S2: =F2 + G2 + H2 -> 1989 | T2: =(F2 + G2 + H2) / I2 -> 0.090759754
A3: P002 | B3: Twitter | C3: 45750 | D3: Text | E3: Check out our latest text on twitter! | F3: 4054 | G3: 389 | H3: 493 | I3: 64864 | J3: 64383 | K3: 117 | L3: #PepsiCoRefresh | M3: #BetterWithPepsi | O3: FestiveRadiance | P3: =IFS( O3="SummerSplash", DATE(2024,6,15), O3="FestiveRadiance", DATE(2024,10,1), O3="NewYearRefresh", DATE(2024,12,25), O3="DailyWellness", DATE(2025,3,1) ) -> 45566 | Q3: =IFS( O3="SummerSplash", DATE(2024,7,15), O3="FestiveRadiance", DATE(2024,10,31), O3="NewYearRefresh", DATE(2025,1,10), O3="DailyWellness", DATE(2025,3,31) ) -> 45596 | R3: =IF(C3 < N3, "Before Campaign", IF(AND(C3 >= N3, C3 <= O3), "During Campaign", "After Campaign")) -> During Campaign | S3: =F3 + G3 + H3 -> 4936 | T3: =(F3 + G3 + H3) / I3 -> 0.076097681
A4: P003 | B4: YouTube | C4: 45789 | D4: Reel | E4: Check out our latest reel on youtube! | F4: 2795 | G4: 105 | H4: 49 | I4: 53105 | J4: 52307 | K4: 204 | L4: #PepsiCoRefresh | O4: NewYearRefresh | P4: =IFS( O4="SummerSplash", DATE(2024,6,15), O4="FestiveRadiance", DATE(2024,10,1), O4="NewYearRefresh", DATE(2024,12,25), O4="DailyWellness", DATE(2025,3,1) ) -> 45651 | Q4: =IFS( O4="SummerSplash", DATE(2024,7,15), O4="FestiveRadiance", DATE(2024,10,31), O4="NewYearRefresh", DATE(2025,1,10), O4="DailyWellness", DATE(2025,3,31) ) -> 45667 | R4: =IF(C4 < N4, "Before Campaign", IF(AND(C4 >= N4, C4 <= O4), "During Campaign", "After Campaign")) -> During Campaign | S4: =F4 + G4 + H4 -> 2949 | T4: =(F4 + G4 + H4) / I4 -> 0.055531494
A5: P004 | B5: Instagram | C5: 45516 | D5: Story | E5: Check out our latest story on instagram! | F5: 2404 | G5: 363 | H5: 138 | I5: 19232 | J5: 18636 | K5: 128 | L5: #ThirstyForMore | O5: DailyWellness | P5: =IFS( O5="SummerSplash", DATE(2024,6,15), O5="FestiveRadiance", DATE(2024,10,1), O5="NewYearRefresh", DATE(2024,12,25), O5="DailyWellness", DATE(2025,3,1) ) -> 45717 | Q5: =IFS( O5="SummerSplash", DATE(2024,7,15), O5="FestiveRadiance", DATE(2024,10,31), O5="NewYearRefresh", DATE(2025,1,10), O5="DailyWellness", DATE(2025,3,31) ) -> 45747 | R5: =IF(C5 < N5, "Before Campaign", IF(AND(C5 >= N5, C5 <= O5), "During Campaign", "After Campaign")) -> During Campaign | S5: =F5 + G5 + H5 -> 2905 | T5: =(F5 + G5 + H5) / I5 -> 0.15105033
A6: P005 | B6: YouTube | C6: 45469 | D6: Reel | E6: Check out our latest reel on youtube! | F6: 3557 | G6: 687 | H6: 424 | I6: 71140 | J6: 70701 | K6: 224 | L6: #ThirstyForMore | M6: #PepsiCoRefresh | O6: SummerSplash | P6: =IFS( O6="SummerSplash", DATE(2024,6,15), O6="FestiveRadiance", DATE(2024,10,1), O6="NewYearRefresh", DATE(2024,12,25), O6="DailyWellness", DATE(2025,3,1) ) -> 45458 | Q6: =IFS( O6="SummerSplash", DATE(2024,7,15), O6="FestiveRadiance", DATE(2024,10,31), O6="NewYearRefresh", DATE(2025,1,10), O6="DailyWellness", DATE(2025,3,31) ) -> 45488 | R6: =IF(C6 < N6, "Before Campaign", IF(AND(C6 >= N6, C6 <= O6), "During Campaign", "After Campaign")) -> During Campaign | S6: =F6 + G6 + H6 -> 4668 | T6: =(F6 + G6 + H6) / I6 -> 0.065617093
A7: P006 | B7: Facebook | C7: 45596 | D7: Carousel | E7: Check out our latest carousel on facebook! | F7: 2945 | G7: 930 | H7: 355 | I7: 23560 | J7: 23275 | K7: 256 | L7: #PepsiCoRefresh | O7: FestiveRadiance | P7: =IFS( O7="SummerSplash", DATE(2024,6,15), O7="FestiveRadiance", DATE(2024,10,1), O7="NewYearRefresh", DATE(2024,12,25), O7="DailyWellness", DATE(2025,3,1) ) -> 45566 | Q7: =IFS( O7="SummerSplash", DATE(2024,7,15), O7="FestiveRadiance", DATE(2024,10,31), O7="NewYearRefresh", DATE(2025,1,10), O7="DailyWellness", DATE(2025,3,31) ) -> 45596 | R7: =IF(C7 < N7, "Before Campaign", IF(AND(C7 >= N7, C7 <= O7), "During Campaign", "After Campaign")) -> During Campaign | S7: =F7 + G7 + H7 -> 4230 | T7: =(F7 + G7 + H7) / I7 -> 0.1795416
A8: P007 | B8: Twitter | C8: 45467 | D8: Carousel | E8: Check out our latest carousel on twitter! | F8: 3860 | G8: 201 | H8: 279 | I8: 61760 | J8: 61660 | K8: 235 | L8: #PepsiCoRefresh | O8: FestiveRadiance | P8: =IFS( O8="SummerSplash", DATE(2024,6,15), O8="FestiveRadiance", DATE(2024,10,1), O8="NewYearRefresh", DATE(2024,12,25), O8="DailyWellness", DATE(2025,3,1) ) -> 45566 | Q8: =IFS( O8="SummerSplash", DATE(2024,7,15), O8="FestiveRadiance", DATE(2024,10,31), O8="NewYearRefresh", DATE(2025,1,10), O8="DailyWellness", DATE(2025,3,31) ) -> 45596 | R8: =IF(C8 < N8, "Before Campaign", IF(AND(C8 >= N8, C8 <= O8), "During Campaign", "After Campaign")) -> During Campaign | S8: =F8 + G8 + H8 -> 4340 | T8: =(F8 + G8 + H8) / I8 -> 0.070272021
